<?xml version="1.0" encoding="utf-8"?>

<robot xmlns:xacro="http://www.ros.org/wiki/xacro" name="my_arm">

    <link name="world" />

    <link name="base_link">
        <visual>
            <origin xyz="0.0 0.0 0.0" rpy="0 0 0" />
            <geometry>
                <mesh filename="package://my_arm_description/meshes/Base.STL" />
            </geometry>
        </visual>
    </link>

    <joint name="world_to_base_joint" type="fixed">
        <origin xyz="0.0 0.0 0.0" rpy="0 0 0" />
        <parent link="world" />
        <child link="base_link" />
    </joint>

    <link name="shoulder_link">
        <visual>
            <origin xyz="0 0 0" rpy="${pi/2} 0 0" />
            <geometry>
                <mesh filename="package://my_arm_description/meshes/Rotation_Pitch.STL" />
            </geometry>
        </visual>
    </link>

    <joint name="base_to_shoulder_joint" type="revolute">
        <origin xyz="0 -0.0452 0.0165" rpy="0 0 0" />
        <parent link="base_link" />
        <child link="shoulder_link" />
        <axis xyz="0 0 1" />
        <limit upper="${pi/2}" lower="-${pi/2}" effort="1.0" velocity="1.0" />
    </joint>

    <link name="upper_arm_link">
        <visual>
            <origin xyz="0 0 0" rpy="0 ${pi/2} 0" />
            <geometry>
                <mesh filename="package://my_arm_description/meshes/Upper_Arm.STL" />
            </geometry>
        </visual>
    </link>

    <joint name="shoulder_to_upper_arm_joint" type="revolute">
        <origin xyz="0 -0.0306 0.10 " rpy="${pi/2} 0 -${pi/2}" />
        <parent link="shoulder_link" />
        <child link="upper_arm_link" />
        <axis xyz="0 0 1" />
        <limit upper="${pi/2}" lower="-${pi/2}" effort="1.0" velocity="1.0" />
    </joint>

    <link name="lower_arm_link">
        <visual>
            <origin xyz="0 0 0" rpy="0 ${pi/2} 0" />
            <geometry>
                <mesh filename="package://my_arm_description/meshes/Lower_Arm.STL" />
            </geometry>
        </visual>
    </link>

    <joint name="upper_arm_to_lower_arm_joint" type="revolute">
        <origin xyz="0.0276 0.1125 0.0" rpy="0 0 0" />
        <parent link="upper_arm_link" />
        <child link="lower_arm_link" />
        <axis xyz="0 0 1" />
        <limit upper="${pi/2}" lower="-${pi/2}" effort="1.0" velocity="1.0" />
    </joint>

    <link name="wrist_link">
        <visual>
            <origin xyz="0 0 0" rpy="-${pi/2} ${pi/2} 0" />
            <geometry>
                <mesh filename="package://my_arm_description/meshes/Wrist_Pitch_Roll.STL" />
            </geometry>
        </visual>
    </link>

    <joint name="lower_arm_to_wrist_joint" type="revolute">
        <origin xyz="0.135 0.0052 0.0" rpy="0 0 0" />
        <parent link="lower_arm_link" />
        <child link="wrist_link" />
        <axis xyz="0 0 1" />
        <limit upper="${pi/2}" lower="-${pi/2}" effort="1.0" velocity="1.0" />
    </joint>

    <link name="fixed_jaw_link">
        <visual>
            <origin xyz="0 0 0" rpy="-${pi/2} 0 -${pi/2}" />
            <geometry>
                <mesh filename="package://my_arm_description/meshes/Fixed_Jaw.STL" />
            </geometry>
        </visual>
    </link>

    <joint name="wrist_to_fixed_jaw_joint" type="revolute">
        <origin xyz="0.06 0.0 0.0" rpy="0 ${pi/2} 0" />
        <parent link="wrist_link" />
        <child link="fixed_jaw_link" />
        <axis xyz="0 0 1" />
        <limit upper="${pi}" lower="-${pi}" effort="1.0" velocity="1.0" />
 
    </joint>

    <link name="moving_jaw_link">
        <visual>
            <origin xyz="0 0 0" rpy="0 0 0" />
            <geometry>
                <mesh filename="package://my_arm_description/meshes/Moving_Jaw.STL" />
            </geometry>
        </visual>
    </link>

    <joint name="fixed_to_moving_jaw_joint" type="revolute">
        <origin xyz="0.0 0.02 0.0245" rpy="${pi/2} ${pi} -${pi/2}" />
        <parent link="fixed_jaw_link" />
        <child link="moving_jaw_link" />
        <axis xyz="0 0 1" />
        <limit upper="${pi/2}" lower="-${pi/2}" effort="1.0" velocity="1.0" />
        
    </joint>
</robot>